#VRML_SIM R2025a utf8

EXTERNPROTO "https://raw.githubusercontent.com/cyberbotics/webots/R2025a/projects/objects/backgrounds/protos/TexturedBackground.proto"
EXTERNPROTO "https://raw.githubusercontent.com/cyberbotics/webots/R2025a/projects/objects/backgrounds/protos/TexturedBackgroundLight.proto"
EXTERNPROTO "https://raw.githubusercontent.com/cyberbotics/webots/R2025a/projects/objects/gear/protos/Gear.proto"

WorldInfo {
  info [
    "Example of meshing gears"
  ]
  title "Gears example"
  basicTimeStep 8
}
Viewpoint {
  orientation 0.23278859217604628 0.2022836913726661 0.9512574727997369 4.5230995010799475
  position -0.000711067649379539 0.2984160027654809 -0.15122698036356375
}
TexturedBackground {
  texture "empty_office"
}
TexturedBackgroundLight {
}
Robot {
  rotation 0 0 1 1.5708
  children [
    DEF MOTORIZED HingeJoint {
      jointParameters HingeJointParameters {
      }
      device [
        PositionSensor {
        }
        RotationalMotor {
        }
      ]
      endPoint Gear {
        translation 0 0 0
        rotation 1 0 0 0
        appearance PBRAppearance {
          baseColor 0.8 0 0
          roughness 0.5
        }
        teeth 30
        toothDepth 0.007
        density 0.01
        bodyBoundingObject FALSE
        teethBoundingObject TRUE
      }
    }
    DEF PASSIVE HingeJoint {
      jointParameters HingeJointParameters {
        anchor 0 0.086 0
        dampingConstant 1e-08
      }
      device [
        PositionSensor {
          name "position sensor2"
        }
      ]
      endPoint Gear {
        translation 0 0.086 0
        rotation 1 0 0 0
        appearance PBRAppearance {
          baseColor 0.203922 0.396078 0.643137
          roughness 0.5
        }
        name "gear2"
        teeth 36
        toothDepth 0.005
        density 0.01
        bodyBoundingObject FALSE
        teethBoundingObject TRUE
      }
    }
  ]
  controller "gears"
  selfCollision TRUE
}
