#VRML_SIM R2025a utf8

EXTERNPROTO "https://raw.githubusercontent.com/cyberbotics/webots/R2025a/projects/objects/backgrounds/protos/TexturedBackground.proto"
EXTERNPROTO "https://raw.githubusercontent.com/cyberbotics/webots/R2025a/projects/objects/backgrounds/protos/TexturedBackgroundLight.proto"
EXTERNPROTO "https://raw.githubusercontent.com/cyberbotics/webots/R2025a/projects/objects/gear/protos/Gear.proto"

WorldInfo {
  info [
    "Example of meshing gears"
  ]
  title "Gears example"
  basicTimeStep 8
}
Viewpoint {
  orientation 0.05116609449418922 0.04897515518018283 0.9974885788565645 4.666126947259656
  position -0.027806762208029065 0.5177016422797439 -0.05623090987692434
}
TexturedBackground {
  texture "empty_office"
}
TexturedBackgroundLight {
}
Robot {
  rotation 0 0 1 1.5708
  children [
    DEF MOTORIZED HingeJoint {
      jointParameters HingeJointParameters {
        anchor 0 -0.03 0
      }
      device [
        PositionSensor {
        }
        RotationalMotor {
        }
      ]
      endPoint Gear {
        translation 0 -0.03 0
        rotation 1 0 0 0.9162986938995744
        appearance PBRAppearance {
          baseColor 0.8 0 0
          roughness 0.5
        }
        teeth 30
        pitchRadius 0.07
        toothDepth 0.007
        density 50
        bodyBoundingObject FALSE
        teethBoundingObject TRUE
      }
    }
    DEF PASSIVE HingeJoint {
      jointParameters HingeJointParameters {
        anchor 0 0.083 0.01
        dampingConstant 1e-08
      }
      device [
        PositionSensor {
          name "position sensor2"
        }
      ]
      endPoint Gear {
        translation 0 0.083 0.01
        rotation 1 0 0 0
        appearance PBRAppearance {
          baseColor 0.203922 0.396078 0.643137
          roughness 0.5
        }
        name "gear2"
        teeth 30
        width 0.02
        innerRadius 0.03
        pitchRadius 0.01
        toothDepth 0.003
        density 50
        bodyBoundingObject FALSE
        teethBoundingObject TRUE
      }
    }
  ]
  controller "gears2"
  selfCollision TRUE
}
